Workbook

Sheet IU Major Match
A1: School | B1: Level | C1: Major | D1: Title | E1: IU Match
A2: SoAS | B2: underGraduate | C2: ADVR | D2: Bachelor of Arts in Communication Arts - Advertising | E2: Major exists in IU
A3: SoAS | B3: underGraduate | C3: BACAD | D3: Bachelor of Communication Arts (Advertising) | E3: Major exists in IU
A4: SoAS | B4: underGraduate | C4: BACJO | D4: Bachelor of Communication Arts (Journalism) | E4: Major exists in IU
A5: SoAS | B5: underGraduate | C5: BACPR | D5: Bachelor of Communication Arts (Public Relations) | E5: Major exists in IU
A6: SoAS | B6: underGraduate | C6: BACRT | D6: Bachelor of Communication Arts (Radio and Television) | E6: Major exists in IU
A7: SoAS | B7: underGraduate | C7: BBIOC | D7: Bachelor of Biochemisrty | E7: Major Dont exists in IU
A8: SoAS | B8: underGraduate | C8: BBIOL | D8: Bachelor of Biology | E8: Major Dont exists in IU
A9: SoAS | B9: underGraduate | C9: BBMED | D9: Bachelor of Biomedical Sciences | E9: Major Dont exists in IU
A10: SoAS | B10: underGraduate | C10: BCSCI | D10: Bachelor of Computer Science | E10: Major exists in IU
A11: SoAS | B11: underGraduate | C11: BCSIT | D11: Bachelor of Information TechMajor Dont exists in IUlogy | E11: Major exists in IU
A12: SoAS | B12: underGraduate | C12: BFDST | D12: Bachelor of Food TechMajor Dont exists in IUlogy | E12: Major Dont exists in IU
... A70: SoBU | B70: graduate | C70: MFIN | D70: Master of Business Administration in Finance | E70: Major Dont exists in IU

Sheet Not ML Reg ML
A1: ID | B1: AppID | C1: First | D1: Middle | E1: Last | F1: Campus | G1: School | H1: Level | I1: Major | J1: Title | K1: IU Major can Match? | L1: Mobile | M1: Enrolled Semester | N1: Major Credits | O1: Completed | P1: Reg. Credits | Q1: Left Credits | R1: % Completed + Registered | S1: Category | T1: Expected # Semesters to graduate | U1: # years to graduate
A2: 12130763 | B2: 171351 | C2: Abbas | D2: Hassan | E2: Hussein | F2: Beirut | G2: SoEN | H2: underGraduate | I2: MENG | J2: Bachelor of Science in Mechanical Engineering | K2: =VLOOKUP(J2,'IU Major Match'!$D$2:$E$65,2,FALSE) -> Can be Transferred to Bachelor of Engineering | L2: 96171263223 | M2: Fall 2021 - 2022 | N2: 108 | O2: 81 | P2: 6 | Q2: 21 | R2: =(O2+P2)/N2 -> 0.80555556 | S2: =IF(R2<=50%,"=<50",">50") -> >50 | T2: =ROUNDUP(Q2/15,0) -> 2 | U2: =T2/2 -> 1
A3: 22131118 | B3: 175941 | C3: Aida | D3: Ohannes | E3: Minassian | F3: Bekaa | G3: SoAS | H3: underGraduate | I3: IDES | J3: Bachelor of Arts in Interior Design | K3: =VLOOKUP(J3,'IU Major Match'!$D$2:$E$65,2,FALSE) -> Major exists in IU | L3: 96181708432 | M3: Fall 2021 - 2022 | N3: 99 | O3: 78 | P3: 9 | Q3: 12 | R3: =(O3+P3)/N3 -> 0.87878788 | S3: =IF(R3<=50%,"=<50",">50") -> >50 | T3: =ROUNDUP(Q3/15,0) -> 1 | U3: =T3/2 -> 0.5
A4: 12530729 | B4: 219551 | C4: Alain | D4: George | E4: Ibrahim | F4: Beirut | G4: SoEN | H4: underGraduate | I4: CENG | J4: Bachelor of Science in Computer Engineering | K4: =VLOOKUP(J4,'IU Major Match'!$D$2:$E$65,2,FALSE) -> Can be Transferred to Bachelor of Engineering | L4: 96171717936 | M4: Fall 2025 - 2026 | N4: 108 | O4: 3 | P4: 10 | Q4: 99 | R4: =(O4+P4)/N4 -> 0.12037037 | S4: =IF(R4<=50%,"=<50",">50") -> =<50 | T4: =ROUNDUP(Q4/15,0) -> 7 | U4: =T4/2 -> 3.5
A5: 12510123 | B5: 217740 | C5: Ali | D5: Hussein | E5: El Zein | F5: Beirut | G5: SoBU | H5: underGraduate | I5: BBAMIS | J5: Bachelor of Business Administration - Management of Information Systems Concentration | K5: =VLOOKUP(J5,'IU Major Match'!$D$2:$E$65,2,FALSE) -> Major exists in IU | L5: 96176928192 | M5: Spring 2024 - 2025 | N5: 99 | O5: 30 | P5: 18 | Q5: 51 | R5: =(O5+P5)/N5 -> 0.48484848 | S5: =IF(R5<=50%,"=<50",">50") -> =<50 | T5: =ROUNDUP(Q5/15,0) -> 4 | U5: =T5/2 -> 2
A6: 12133696 | B6: 175143 | C6: Ali | D6: Mohammad | E6: Taleb | F6: Beirut | G6: SoBU | H6: underGraduate | I6: BMIS | J6: Bachelor of Business Administration in Management Information Systems | K6: =VLOOKUP(J6,'IU Major Match'!$D$2:$E$65,2,FALSE) -> Major exists in IU | L6: 96181998037 | M6: Fall 2021 - 2022 | N6: 99 | O6: 28 | P6: 9 | Q6: 63 | R6: =(O6+P6)/N6 -> 0.37373737 | S6: =IF(R6<=50%,"=<50",">50") -> =<50 | T6: =ROUNDUP(Q6/15,0) -> 5 | U6: =T6/2 -> 2.5
A7: 12431190 | B7: 211045 | C7: Anthony | D7: Charbel | E7: Btiech | F7: Beirut | G7: SoEN | H7: underGraduate | I7: SURV | J7: Bachelor of Science in Surveying Engineering | K7: =VLOOKUP(J7,'IU Major Match'!$D$2:$E$65,2,FALSE) -> Can be Transferred to Bachelor of Engineering | L7: 76546827 | M7: Fall 2024 - 2025 | N7: 108 | O7: 18 | P7: 13 | Q7: 77 | R7: =(O7+P7)/N7 -> 0.28703704 | S7: =IF(R7<=50%,"=<50",">50") -> =<50 | T7: =ROUNDUP(Q7/15,0) -> 6 | U7: =T7/2 -> 3
A8: 82330128 | B8: 200973 | C8: Anthony | D8: Gerges | E8: Fakhry | F8: Rayak | G8: SoBU | H8: underGraduate | I8: BMGT | J8: Bachelor of Business Administration in Business Management | K8: =VLOOKUP(J8,'IU Major Match'!$D$2:$E$65,2,FALSE) -> Major exists in IU | L8: 70496292 | M8: Fall 2023 - 2024 | N8: 99 | O8: 36 | P8: 12 | Q8: 51 | R8: =(O8+P8)/N8 -> 0.48484848 | S8: =IF(R8<=50%,"=<50",">50") -> =<50 | T8: =ROUNDUP(Q8/15,0) -> 4 | U8: =T8/2 -> 2
A9: 31630651 | B9: 106423 | C9: Aya | D9: Youssef | E9: Ayoub | F9: Saida | G9: SoAS | H9: underGraduate | I9: IDES | J9: Bachelor of Arts in Interior Design | K9: =VLOOKUP(J9,'IU Major Match'!$D$2:$E$65,2,FALSE) -> Major exists in IU | L9: 96181740625 | M9: Fall 2016 - 2017 | N9: 99 | O9: 95 | P9: 4 | Q9: 0 | R9: =(O9+P9)/N9 -> 1 | S9: =IF(R9<=50%,"=<50",">50") -> >50 | T9: =ROUNDUP(Q9/15,0) -> 0 | U9: =T9/2 -> 0
A10: 12120062 | B10: 200183 | C10: Batoul | D10: Fadi | E10: Shucair | F10: Beirut | G10: SoAS | H10: underGraduate | I10: NUTR | J10: Bachelor of Science in Nutrition and Dietetics | K10: =VLOOKUP(J10,'IU Major Match'!$D$2:$E$65,2,FALSE) -> Major Dont exists in IU | L10: 76500763 | M10: Fall 2023 - 2024 | N10: 99 | O10: 55 | P10: 18 | Q10: 26 | R10: =(O10+P10)/N10 -> 0.73737374 | S10: =IF(R10<=50%,"=<50",">50") -> >50 | T10: =ROUNDUP(Q10/15,0) -> 2 | U10: =T10/2 -> 1
A11: 22430656 | B11: 215342 | C11: Carlen | D11: Melhem | E11: Jasser | F11: Bekaa | G11: SoBU | H11: underGraduate | I11: BMKT | J11: Bachelor of Business Administration in Marketing | K11: =VLOOKUP(J11,'IU Major Match'!$D$2:$E$65,2,FALSE) -> Major exists in IU | L11: 96176784215 | M11: Fall 2024 - 2025 | N11: 99 | O11: 18 | P11: 16 | Q11: 69 | R11: =(O11+P11)/N11 -> 0.34343434 | S11: =IF(R11<=50%,"=<50",">50") -> =<50 | T11: =ROUNDUP(Q11/15,0) -> 5 | U11: =T11/2 -> 2.5
A12: 42420001 | B12: 209188 | C12: Celine | D12: Habib | E12: Nahra | F12: Nabatieh | G12: SoBU | H12: underGraduate | I12: BMGT | J12: Bachelor of Business Administration in Business Management | K12: =VLOOKUP(J12,'IU Major Match'!$D$2:$E$65,2,FALSE) -> Major exists in IU | L12: 96181663090 | M12: Summer 2023 - 2024 | N12: 99 | O12: 69 | P12: 15 | Q12: 15 | R12: =(O12+P12)/N12 -> 0.84848485 | S12: =IF(R12<=50%,"=<50",">50") -> >50 | T12: =ROUNDUP(Q12/15,0) -> 1 | U12: =T12/2 -> 0.5
A13: 82430228 | B13: 215761 | C13: Charbel | D13: Elias | E13: Abboud | F13: Rayak | G13: SoAS | H13: underGraduate | I13: CSIT | J13: Bachelor of Science in Information Technology | K13: =VLOOKUP(J13,'IU Major Match'!$D$2:$E$65,2,FALSE) -> Major exists in IU | L13: 3488535 | M13: Fall 2024 - 2025 | N13: 100 | O13: 9 | P13: 12 | Q13: 79 | R13: =(O13+P13)/N13 -> 0.21 | S13: =IF(R13<=50%,"=<50",">50") -> =<50 | T13: =ROUNDUP(Q13/15,0) -> 6 | U13: =T13/2 -> 3
... A83: 12610109 | B83: 227235 | C83: Yara | D83: Tarek | E83: Kehde | F83: Beirut | G83: SoAS | H83: underGraduate | I83: BIDES | J83: Bachelor of Interior Design | K83: =VLOOKUP(J83,'IU Major Match'!$D$2:$E$65,2,FALSE) -> Major exists in IU | L83: 96176330780 | M83: Spring 2025 - 2026 | N83: 99 | O83: 0 | P83: 10 | Q83: 99 | R83: =(O83+P83)/N83 -> 0.1010101 | S83: =IF(R83<=50%,"=<50",">50") -> =<50 | T83: =ROUNDUP(Q83/15,0) -> 7 | U83: =T83/2 -> 3.5

Sheet ML Std Enrolled but not ML
A1: ID | B1: AppID | C1: First | D1: Middle | E1: Last | F1: Campus | G1: School | H1: Level | I1: Major | J1: Title | K1: IU Major can Match? | L1: Mobile | M1: Enrolled Semester | N1: Major Credits | O1: Completed | P1: Reg. Credits | Q1: Left Credits | R1: % Completed + Registered | S1: Category | T1: Expected # Semesters to graduate | U1: # years to graduate
A2: 62030065 | B2: 212080 | C2: Abdo | D2: Zakhia | E2: Sebaaly | F2: Mount Lebanon | G2: SoEN | H2: graduate | I2: MEENG | J2: Masters of Science in Electrical Engineering | K2: =VLOOKUP(J2,'IU Major Match'!$D$2:$E$65,2,FALSE) -> #N/A | L2: 76460069 | M2: Fall 2024 - 2025 | N2: 52 | O2: 39 | P2: 13 | Q2: 0 | R2: =(O2+P2)/N2 -> 1 | S2: =IF(R2<=50%,"=<50",">50") -> >50 | T2: =ROUNDUP(Q2/15,0) -> 0 | U2: =T2/2 -> 0
A3: 61730314 | B3: 123653 | C3: Abdullah | D3: Marwan | E3: Dib | F3: Mount Lebanon | G3: SoBU | H3: underGraduate | I3: BAIS | J3: Bachelor of Business Administration in Accounting Information Systems | K3: =VLOOKUP(J3,'IU Major Match'!$D$2:$E$65,2,FALSE) -> Major Dont exists in IU | L3: 96171862670 | M3: Fall 2017 - 2018 | N3: 99 | O3: 54 | P3: 18 | Q3: 27 | R3: =(O3+P3)/N3 -> 0.72727273 | S3: =IF(R3<=50%,"=<50",">50") -> >50 | T3: =ROUNDUP(Q3/15,0) -> 2 | U3: =T3/2 -> 1
A4: 62130065 | B4: 224410 | C4: Ahmad | D4: Hassan | E4: Najde | F4: Mount Lebanon | G4: SoEN | H4: graduate | I4: MMENG | J4: Masters of Science in Mechanical Engineering | K4: =VLOOKUP(J4,'IU Major Match'!$D$2:$E$65,2,FALSE) -> #N/A | L4: 96171456137 | M4: Fall 2025 - 2026 | N4: 52 | O4: 13 | P4: 13 | Q4: 26 | R4: =(O4+P4)/N4 -> 0.5 | S4: =IF(R4<=50%,"=<50",">50") -> =<50 | T4: =ROUNDUP(Q4/15,0) -> 2 | U4: =T4/2 -> 1
A5: 61930339 | B5: 208836 | C5: Alex | D5: Maroun | E5: Mouawad | F5: Mount Lebanon | G5: SoEN | H5: graduate | I5: MCCE | J5: Masters of Science in Computer and Communications Engineering | K5: =VLOOKUP(J5,'IU Major Match'!$D$2:$E$65,2,FALSE) -> #N/A | L5: 3438162 | M5: Spring 2023 - 2024 | N5: 52 | O5: 15 | P5: 13 | Q5: 22 | R5: =(O5+P5)/N5 -> 0.53846154 | S5: =IF(R5<=50%,"=<50",">50") -> >50 | T5: =ROUNDUP(Q5/15,0) -> 2 | U5: =T5/2 -> 1
A6: 62230151 | B6: 186438 | C6: Ali | D6: Mahmoud | E6: Berro | F6: Mount Lebanon | G6: SoAS | H6: underGraduate | I6: CSIT | J6: Bachelor of Science in Information Technology | K6: =VLOOKUP(J6,'IU Major Match'!$D$2:$E$65,2,FALSE) -> Major exists in IU | L6: 96171466634 | M6: Fall 2022 - 2023 | N6: 100 | O6: 91 | P6: 9 | Q6: 0 | R6: =(O6+P6)/N6 -> 1 | S6: =IF(R6<=50%,"=<50",">50") -> >50 | T6: =ROUNDUP(Q6/15,0) -> 0 | U6: =T6/2 -> 0
A7: 61810014 | B7: 223663 | C7: Anahid | D7: Kevork | E7: Nalbandian | F7: Mount Lebanon | G7: SoED | H7: graduate | I7: TDLA | J7: Teaching Diploma in Languages | K7: =VLOOKUP(J7,'IU Major Match'!$D$2:$E$65,2,FALSE) -> #N/A | L7: 71064490 | M7: Fall 2025 - 2026 | N7: 28 | O7: 14 | P7: 14 | Q7: 0 | R7: =(O7+P7)/N7 -> 1 | S7: =IF(R7<=50%,"=<50",">50") -> >50 | T7: =ROUNDUP(Q7/15,0) -> 0 | U7: =T7/2 -> 0
A8: 62330313 | B8: 206119 | C8: Anie | D8: Imad | E8: Moussa | F8: Mount Lebanon | G8: SoAS | H8: underGraduate | I8: BIOC | J8: Bachelor of Science in Biochemistry | K8: =VLOOKUP(J8,'IU Major Match'!$D$2:$E$65,2,FALSE) -> Major Dont exists in IU | L8: 96179315884 | M8: Fall 2023 - 2024 | N8: 99 | O8: 83 | P8: 11 | Q8: 5 | R8: =(O8+P8)/N8 -> 0.94949495 | S8: =IF(R8<=50%,"=<50",">50") -> >50 | T8: =ROUNDUP(Q8/15,0) -> 1 | U8: =T8/2 -> 0.5
A9: 62330077 | B9: 201882 | C9: Anna Maria | D9: Tony | E9: Breidy | F9: Mount Lebanon | G9: SoPH | H9: underGraduate | I9: PrPH | J9: Pre-Pharmacy | K9: =VLOOKUP(J9,'IU Major Match'!$D$2:$E$65,2,FALSE) -> Major Dont exists in IU | L9: 96171749937 | M9: Fall 2023 - 2024 | N9: 65 | O9: 48 | P9: 15 | Q9: 2 | R9: =(O9+P9)/N9 -> 0.96923077 | S9: =IF(R9<=50%,"=<50",">50") -> >50 | T9: =ROUNDUP(Q9/15,0) -> 1 | U9: =T9/2 -> 0.5
A10: 62130243 | B10: 220311 | C10: Anthony | D10: Toni | E10: Makhoul | F10: Mount Lebanon | G10: SoEN | H10: graduate | I10: MMENG | J10: Masters of Science in Mechanical Engineering | K10: =VLOOKUP(J10,'IU Major Match'!$D$2:$E$65,2,FALSE) -> #N/A | L10: 71649521 | M10: Fall 2025 - 2026 | N10: 52 | O10: 13 | P10: 13 | Q10: 26 | R10: =(O10+P10)/N10 -> 0.5 | S10: =IF(R10<=50%,"=<50",">50") -> =<50 | T10: =ROUNDUP(Q10/15,0) -> 2 | U10: =T10/2 -> 1
A11: 62130170 | B11: 212082 | C11: Antoine | D11: Fares | E11: Saliba | F11: Mount Lebanon | G11: SoEN | H11: graduate | I11: MCCE | J11: Masters of Science in Computer and Communications Engineering | K11: =VLOOKUP(J11,'IU Major Match'!$D$2:$E$65,2,FALSE) -> #N/A | L11: 81233497 | M11: Fall 2024 - 2025 | N11: 52 | O11: 40 | P11: 12 | Q11: 0 | R11: =(O11+P11)/N11 -> 1 | S11: =IF(R11<=50%,"=<50",">50") -> >50 | T11: =ROUNDUP(Q11/15,0) -> 0 | U11: =T11/2 -> 0
A12: 61710023 | B12: 111694 | C12: Antonella | D12: Joseph | E12: Onikian | F12: Mount Lebanon | G12: SoAS | H12: underGraduate | I12: BIOC | J12: Bachelor of Science in Biochemistry | K12: =VLOOKUP(J12,'IU Major Match'!$D$2:$E$65,2,FALSE) -> Major Dont exists in IU | L12: 96171157252 | M12: Spring 2016 - 2017 | N12: 99 | O12: 38 | P12: 11 | Q12: 50 | R12: =(O12+P12)/N12 -> 0.49494949 | S12: =IF(R12<=50%,"=<50",">50") -> =<50 | T12: =ROUNDUP(Q12/15,0) -> 4 | U12: =T12/2 -> 2
A13: 62030312 | B13: 219641 | C13: Antonios | D13: Maroun | E13: Daher | F13: Mount Lebanon | G13: SoEN | H13: graduate | I13: MMENG | J13: Masters of Science in Mechanical Engineering | K13: =VLOOKUP(J13,'IU Major Match'!$D$2:$E$65,2,FALSE) -> #N/A | L13: 96170723876 | M13: Fall 2025 - 2026 | N13: 52 | O13: 13 | P13: 13 | Q13: 26 | R13: =(O13+P13)/N13 -> 0.5 | S13: =IF(R13<=50%,"=<50",">50") -> =<50 | T13: =ROUNDUP(Q13/15,0) -> 2 | U13: =T13/2 -> 1
... A154: 61930254 | B154: 192425 | C154: Zakar | D154: Varoujan | E154: Zakarian | F154: Mount Lebanon | G154: SoBU | H154: graduate | I154: MECO | J154: Master of Business Administration in Financial Economics | K154: =VLOOKUP(J154,'IU Major Match'!$D$2:$E$65,2,FALSE) -> #N/A | L154: 76170434 | M154: Fall 2022 - 2023 | N154: 39 | O154: 36 | P154: 3 | Q154: 0 | R154: =(O154+P154)/N154 -> 1 | S154: =IF(R154<=50%,"=<50",">50") -> >50 | T154: =ROUNDUP(Q154/15,0) -> 0 | U154: =T154/2 -> 0

Sheet ML Std Enrolled in ML
A1: ID | B1: AppID | C1: First | D1: Middle | E1: Last | F1: Campus | G1: School | H1: Level | I1: Major | J1: Title | K1: IU Major can Match? | L1: Mobile | M1: Enrolled Semester | N1: Major Credits | O1: Completed | P1: Reg. Credits | Q1: Left Credits | R1: % Completed + Registered | S1: Category | T1: Expected # Semesters to graduate | U1: # years to graduate
A2: 62130182 | B2: 172787 | C2: Abbas | D2: Raed | E2: Mostafa | F2: Mount Lebanon | G2: SoEN | H2: underGraduate | I2: TENG | J2: Bachelor of Science in Communication Engineering | K2: =VLOOKUP(J2,'IU Major Match'!$D$2:$E$65,2,FALSE) -> Can be Transferred to Bachelor of Engineering | L2: 76499125 | M2: Fall 2021 - 2022 | N2: 108 | O2: 50 | P2: 14 | Q2: 44 | R2: =(O2+P2)/N2 -> 0.59259259 | S2: =IF(R2<=50%,"=<50",">50") -> >50 | T2: =ROUNDUP(Q2/15,0) -> 3 | U2: =T2/2 -> 1.5
A3: 62610013 | B3: 227138 | C3: Abdallah | D3: Naser | E3: Arab | F3: Mount Lebanon | G3: SoEN | H3: underGraduate | I3: MENG | J3: Bachelor of Science in Mechanical Engineering | K3: =VLOOKUP(J3,'IU Major Match'!$D$2:$E$65,2,FALSE) -> Can be Transferred to Bachelor of Engineering | L3: 71732748 | M3: Spring 2025 - 2026 | N3: 108 | O3: 0 | P3: 19 | Q3: 112 | R3: =(O3+P3)/N3 -> 0.17592593 | S3: =IF(R3<=50%,"=<50",">50") -> =<50 | T3: =ROUNDUP(Q3/15,0) -> 8 | U3: =T3/2 -> 4
A4: 62330246 | B4: 205930 | C4: Abigail | D4: Sami | E4: Al Nashef | F4: Mount Lebanon | G4: SoAS | H4: underGraduate | I4: GDES | J4: Bachelor of Arts in Graphic Design | K4: =VLOOKUP(J4,'IU Major Match'!$D$2:$E$65,2,FALSE) -> Major exists in IU | L4: 96171595630 | M4: Fall 2023 - 2024 | N4: 99 | O4: 90 | P4: 9 | Q4: 0 | R4: =(O4+P4)/N4 -> 1 | S4: =IF(R4<=50%,"=<50",">50") -> >50 | T4: =ROUNDUP(Q4/15,0) -> 0 | U4: =T4/2 -> 0
A5: 62130165 | B5: 168811 | C5: Adam | D5: Samir | E5: Jaber | F5: Mount Lebanon | G5: SoBU | H5: underGraduate | I5: BMKT | J5: Bachelor of Business Administration in Marketing | K5: =VLOOKUP(J5,'IU Major Match'!$D$2:$E$65,2,FALSE) -> Major exists in IU | L5: 96178747241 | M5: Fall 2021 - 2022 | N5: 99 | O5: 45 | P5: 12 | Q5: 42 | R5: =(O5+P5)/N5 -> 0.57575758 | S5: =IF(R5<=50%,"=<50",">50") -> >50 | T5: =ROUNDUP(Q5/15,0) -> 3 | U5: =T5/2 -> 1.5
A6: 62530183 | B6: 223863 | C6: Adel | D6: Samer | E6: Al Taki | F6: Mount Lebanon | G6: SoAS | H6: underGraduate | I6: BBMED | J6: Bachelor of Biomedical Sciences | K6: =VLOOKUP(J6,'IU Major Match'!$D$2:$E$65,2,FALSE) -> Major Dont exists in IU | L6: 96181375307 | M6: Fall 2025 - 2026 | N6: 105 | O6: 0 | P6: 10 | Q6: 102 | R6: =(O6+P6)/N6 -> 0.095238095 | S6: =IF(R6<=50%,"=<50",">50") -> =<50 | T6: =ROUNDUP(Q6/15,0) -> 7 | U6: =T6/2 -> 3.5
A7: 62330243 | B7: 205902 | C7: Adolphe | D7: Edgard | E7: Sakr | F7: Mount Lebanon | G7: SoAS | H7: underGraduate | I7: CSCI | J7: Bachelor of Science in Computer Science | K7: =VLOOKUP(J7,'IU Major Match'!$D$2:$E$65,2,FALSE) -> Major exists in IU | L7: 79132513 | M7: Fall 2023 - 2024 | N7: 100 | O7: 67 | P7: 15 | Q7: 18 | R7: =(O7+P7)/N7 -> 0.82 | S7: =IF(R7<=50%,"=<50",">50") -> >50 | T7: =ROUNDUP(Q7/15,0) -> 2 | U7: =T7/2 -> 1
A8: 62330336 | B8: 206361 | C8: Ahmad | D8: Amer | E8: Alwan | F8: Mount Lebanon | G8: SoEN | H8: underGraduate | I8: MENG | J8: Bachelor of Science in Mechanical Engineering | K8: =VLOOKUP(J8,'IU Major Match'!$D$2:$E$65,2,FALSE) -> Can be Transferred to Bachelor of Engineering | L8: 96176818968 | M8: Fall 2023 - 2024 | N8: 108 | O8: 59 | P8: 15 | Q8: 34 | R8: =(O8+P8)/N8 -> 0.68518519 | S8: =IF(R8<=50%,"=<50",">50") -> >50 | T8: =ROUNDUP(Q8/15,0) -> 3 | U8: =T8/2 -> 1.5
A9: 62030284 | B9: 160076 | C9: Ahmad | D9: Ali | E9: Fakherdine | F9: Mount Lebanon | G9: SoBU | H9: underGraduate | I9: BMGT | J9: Bachelor of Business Administration in Business Management | K9: =VLOOKUP(J9,'IU Major Match'!$D$2:$E$65,2,FALSE) -> Major exists in IU | L9: 96176073579 | M9: Fall 2020 - 2021 | N9: 99 | O9: 72 | P9: 18 | Q9: 9 | R9: =(O9+P9)/N9 -> 0.90909091 | S9: =IF(R9<=50%,"=<50",">50") -> >50 | T9: =ROUNDUP(Q9/15,0) -> 1 | U9: =T9/2 -> 0.5
A10: 62430219 | B10: 217796 | C10: Ahmad | D10: Badr Eddin | E10: Zeidan | F10: Mount Lebanon | G10: SoBU | H10: underGraduate | I10: BMIS | J10: Bachelor of Business Administration in Management Information Systems | K10: =VLOOKUP(J10,'IU Major Match'!$D$2:$E$65,2,FALSE) -> Major exists in IU | L10: 96181843690 | M10: Fall 2024 - 2025 | N10: 99 | O10: 12 | P10: 15 | Q10: 72 | R10: =(O10+P10)/N10 -> 0.27272727 | S10: =IF(R10<=50%,"=<50",">50") -> =<50 | T10: =ROUNDUP(Q10/15,0) -> 5 | U10: =T10/2 -> 2.5
A11: 62430044 | B11: 210658 | C11: Aisha | D11: Ibrahim | E11: Kamal El Dine | F11: Mount Lebanon | G11: SoAS | H11: underGraduate | I11: NUTR | J11: Bachelor of Science in Nutrition and Dietetics | K11: =VLOOKUP(J11,'IU Major Match'!$D$2:$E$65,2,FALSE) -> Major Dont exists in IU | L11: 81429822 | M11: Fall 2024 - 2025 | N11: 99 | O11: 52 | P11: 17 | Q11: 30 | R11: =(O11+P11)/N11 -> 0.6969697 | S11: =IF(R11<=50%,"=<50",">50") -> >50 | T11: =ROUNDUP(Q11/15,0) -> 2 | U11: =T11/2 -> 1
A12: 62430192 | B12: 212234 | C12: Al Hady Ali | D12: Elias | E12: Deeb | F12: Mount Lebanon | G12: SoAS | H12: underGraduate | I12: CSCI | J12: Bachelor of Science in Computer Science | K12: =VLOOKUP(J12,'IU Major Match'!$D$2:$E$65,2,FALSE) -> Major exists in IU | L12: 96181802108 | M12: Fall 2024 - 2025 | N12: 100 | O12: 29 | P12: 15 | Q12: 56 | R12: =(O12+P12)/N12 -> 0.44 | S12: =IF(R12<=50%,"=<50",">50") -> =<50 | T12: =ROUNDUP(Q12/15,0) -> 4 | U12: =T12/2 -> 2
A13: 62610014 | B13: 227607 | C13: Alaa Eddine | D13: Salah Eddine | E13: Khalife | F13: Mount Lebanon | G13: SoBU | H13: underGraduate | I13: BBAMIS | J13: Bachelor of Business Administration - Management of Information Systems Concentration | K13: =VLOOKUP(J13,'IU Major Match'!$D$2:$E$65,2,FALSE) -> Major exists in IU | L13: 96181969647 | M13: Spring 2025 - 2026 | N13: 99 | O13: 21 | P13: 15 | Q13: 63 | R13: =(O13+P13)/N13 -> 0.36363636 | S13: =IF(R13<=50%,"=<50",">50") -> =<50 | T13: =ROUNDUP(Q13/15,0) -> 5 | U13: =T13/2 -> 2.5
... A74: 62530016 | B74: 219191 | C74: Berfine | D74: Mostafa | E74: Hamo | F74: Mount Lebanon | G74: SoEN | H74: underGraduate | I74: CENG | J74: Bachelor of Science in Computer Engineering | K74: =VLOOKUP(J74,'IU Major Match'!$D$2:$E$65,2,FALSE) -> Can be Transferred to Bachelor of Engineering | L74: 96171299127 | M74: Fall 2025 - 2026 | N74: 108 | O74: 0 | P74: 17 | Q74: 95 | R74: =(O74+P74)/N74 -> 0.15740741 | S74: =IF(R74<=50%,"=<50",">50") -> =<50 | T74: =ROUNDUP(Q74/15,0) -> 7 | U74: =T74/2 -> 3.5
A75: 62230078 | B75: 190070 | C75: Bissan | D75: Wael | E75: Hani | F75: Mount Lebanon | G75: SoAS | H75: underGraduate | I75: BMED | J75: Bachelor of Science in Biomedical Science | K75: =VLOOKUP(J75,'IU Major Match'!$D$2:$E$65,2,FALSE) -> Major Dont exists in IU | L75: 70 824 314 | M75: Fall 2022 - 2023 | N75: 105 | O75: 90 | P75: 9 | Q75: 6 | R75: =(O75+P75)/N75 -> 0.94285714 | S75: =IF(R75<=50%,"=<50",">50") -> >50 | T75: =ROUNDUP(Q75/15,0) -> 1 | U75: =T75/2 -> 0.5
A76: 62330123 | B76: 199887 | C76: Bouchra | D76: Elias | E76: Ibrahim | F76: Mount Lebanon | G76: SoBU | H76: underGraduate | I76: BMKT | J76: Bachelor of Business Administration in Marketing | K76: =VLOOKUP(J76,'IU Major Match'!$D$2:$E$65,2,FALSE) -> Major exists in IU | L76: 71690688 | M76: Fall 2023 - 2024 | N76: 99 | O76: 81 | P76: 18 | Q76: 0 | R76: =(O76+P76)/N76 -> 1 | S76: =IF(R76<=50%,"=<50",">50") -> >50 | T76: =ROUNDUP(Q76/15,0) -> 0 | U76: =T76/2 -> 0
A77: 62310012 | B77: 196956 | C77: Bryan | D77: Simon | E77: Zaklit | F77: Mount Lebanon | G77: SoEN | H77: underGraduate | I77: MENG | J77: Bachelor of Science in Mechanical Engineering | K77: =VLOOKUP(J77,'IU Major Match'!$D$2:$E$65,2,FALSE) -> Can be Transferred to Bachelor of Engineering | L77: 96181911074 | M77: Spring 2022 - 2023 | N77: 108 | O77: 88 | P77: 17 | Q77: 3 | R77: =(O77+P77)/N77 -> 0.97222222 | S77: =IF(R77<=50%,"=<50",">50") -> >50 | T77: =ROUNDUP(Q77/15,0) -> 1 | U77: =T77/2 -> 0.5
A78: 62430261 | B78: 215036 | C78: Caitlen | D78: Samir | E78: Fares | F78: Mount Lebanon | G78: SoAS | H78: underGraduate | I78: IDES | J78: Bachelor of Arts in Interior Design | K78: =VLOOKUP(J78,'IU Major Match'!$D$2:$E$65,2,FALSE) -> Major exists in IU | L78: 71678133 | M78: Fall 2024 - 2025 | N78: 99 | O78: 18 | P78: 9 | Q78: 72 | R78: =(O78+P78)/N78 -> 0.27272727 | S78: =IF(R78<=50%,"=<50",">50") -> =<50 | T78: =ROUNDUP(Q78/15,0) -> 5 | U78: =T78/2 -> 2.5
A79: 62530144 | B79: 222515 | C79: Carelle | D79: Elias | E79: Al Khoueiry | F79: Mount Lebanon | G79: SoBU | H79: underGraduate | I79: BBAMK | J79: Bachelor of Business Administration - Marketing Concentration | K79: =VLOOKUP(J79,'IU Major Match'!$D$2:$E$65,2,FALSE) -> Major exists in IU | L79: 76194122 | M79: Fall 2025 - 2026 | N79: 99 | O79: 51 | P79: 15 | Q79: 33 | R79: =(O79+P79)/N79 -> 0.66666667 | S79: =IF(R79<=50%,"=<50",">50") -> >50 | T79: =ROUNDUP(Q79/15,0) -> 3 | U79: =T79/2 -> 1.5
A80: 62330363 | B80: 207372 | C80: Caren | D80: Jihad | E80: Brayteh | F80: Mount Lebanon | G80: SoAS | H80: underGraduate | I80: NUTR | J80: Bachelor of Science in Nutrition and Dietetics | K80: =VLOOKUP(J80,'IU Major Match'!$D$2:$E$65,2,FALSE) -> Major Dont exists in IU | L80: 71737559 | M80: Fall 2023 - 2024 | N80: 99 | O80: 6 | P80: 14 | Q80: 79 | R80: =(O80+P80)/N80 -> 0.2020202 | S80: =IF(R80<=50%,"=<50",">50") -> =<50 | T80: =ROUNDUP(Q80/15,0) -> 6 | U80: =T80/2 -> 3
A81: 62130461 | B81: 178650 | C81: Carine | D81: Mohammad | E81: Hajj Hassan | F81: Mount Lebanon | G81: SoBU | H81: underGraduate | I81: IMGT | J81: Bachelor of Business Administration in International Business Management | K81: =VLOOKUP(J81,'IU Major Match'!$D$2:$E$65,2,FALSE) -> Major exists in IU | L81: 9613921492 | M81: Fall 2021 - 2022 | N81: 99 | O81: 84 | P81: 15 | Q81: 0 | R81: =(O81+P81)/N81 -> 1 | S81: =IF(R81<=50%,"=<50",">50") -> >50 | T81: =ROUNDUP(Q81/15,0) -> 0 | U81: =T81/2 -> 0
A82: 61930148 | B82: 142342 | C82: Carl | D82: Elias | E82: Al Aaraj | F82: Mount Lebanon | G82: SoBU | H82: underGraduate | I82: BMKT | J82: Bachelor of Business Administration in Marketing | K82: =VLOOKUP(J82,'IU Major Match'!$D$2:$E$65,2,FALSE) -> Major exists in IU | L82: 76520324 | M82: Fall 2019 - 2020 | N82: 99 | O82: 60 | P82: 15 | Q82: 24 | R82: =(O82+P82)/N82 -> 0.75757576 | S82: =IF(R82<=50%,"=<50",">50") -> >50 | T82: =ROUNDUP(Q82/15,0) -> 2 | U82: =T82/2 -> 1
A83: 62330175 | B83: 201093 | C83: Carl | D83: Abdo | E83: Mansour | F83: Mount Lebanon | G83: SoAS | H83: underGraduate | I83: GDES | J83: Bachelor of Arts in Graphic Design | K83: =VLOOKUP(J83,'IU Major Match'!$D$2:$E$65,2,FALSE) -> Major exists in IU | L83: 96170638083 | M83: Fall 2023 - 2024 | N83: 99 | O83: 63 | P83: 12 | Q83: 24 | R83: =(O83+P83)/N83 -> 0.75757576 | S83: =IF(R83<=50%,"=<50",">50") -> >50 | T83: =ROUNDUP(Q83/15,0) -> 2 | U83: =T83/2 -> 1
A84: 62330031 | B84: 211142 | C84: Carla | D84: Youssef | E84: Aslanian | F84: Mount Lebanon | G84: SoAS | H84: underGraduate | I84: GDES | J84: Bachelor of Arts in Graphic Design | K84: =VLOOKUP(J84,'IU Major Match'!$D$2:$E$65,2,FALSE) -> Major exists in IU | L84: 96181654910 | M84: Fall 2024 - 2025 | N84: 99 | O84: 45 | P84: 15 | Q84: 39 | R84: =(O84+P84)/N84 -> 0.60606061 | S84: =IF(R84<=50%,"=<50",">50") -> >50 | T84: =ROUNDUP(Q84/15,0) -> 3 | U84: =T84/2 -> 1.5
A85: 62530201 | B85: 224527 | C85: Carla | D85: Yervant | E85: Kevork | F85: Mount Lebanon | G85: SoBU | H85: underGraduate | I85: BBAMK | J85: Bachelor of Business Administration - Marketing Concentration | K85: =VLOOKUP(J85,'IU Major Match'!$D$2:$E$65,2,FALSE) -> Major exists in IU | L85: 96170198006 | M85: Fall 2025 - 2026 | N85: 99 | O85: 0 | P85: 12 | Q85: 87 | R85: =(O85+P85)/N85 -> 0.12121212 | S85: =IF(R85<=50%,"=<50",">50") -> =<50 | T85: =ROUNDUP(Q85/15,0) -> 6 | U85: =T85/2 -> 3
A86: 62430330 | B86: 216998 | C86: Caryne | D86: Sadek | E86: Fakhreddine | F86: Mount Lebanon | G86: SoED | H86: underGraduate | I86: TESL | J86: Bachelor of Education in Teaching English as a Second Language | K86: =VLOOKUP(J86,'IU Major Match'!$D$2:$E$65,2,FALSE) -> Major Dont exists in IU | L86: 71807654 | M86: Fall 2024 - 2025 | N86: 99 | O86: 18 | P86: 9 | Q86: 72 | R86: =(O86+P86)/N86 -> 0.27272727 | S86: =IF(R86<=50%,"=<50",">50") -> =<50 | T86: =ROUNDUP(Q86/15,0) -> 5 | U86: =T86/2 -> 2.5
A87: 62530112 | B87: 222138 | C87: Catalina | D87: Jack | E87: Al Hourany | F87: Mount Lebanon | G87: SoBU | H87: underGraduate | I87: BBAMG | J87: Bachelor of Business Administration - Business Management Concentration | K87: =VLOOKUP(J87,'IU Major Match'!$D$2:$E$65,2,FALSE) -> Major exists in IU | L87: 96178730550 | M87: Fall 2025 - 2026 | N87: 99 | O87: 15 | P87: 18 | Q87: 66 | R87: =(O87+P87)/N87 -> 0.33333333 | S87: =IF(R87<=50%,"=<50",">50") -> =<50 | T87: =ROUNDUP(Q87/15,0) -> 5 | U87: =T87/2 -> 2.5
... A778: 62330078 | B778: 215186 | C778: Zila | D778: Leon | E778: Abdoian | F778: Mount Lebanon | G778: SoBU | H778: underGraduate | I778: BBAA | J778: Bachelor of Business Administration - Accounting Concentration | K778: =VLOOKUP(J778,'IU Major Match'!$D$2:$E$65,2,FALSE) -> Major Dont exists in IU | L778: 81132389 | M778: Fall 2024 - 2025 | N778: 99 | O778: 30 | P778: 12 | Q778: 3 | R778: =(O778+P778)/N778 -> 0.42424242 | S778: =IF(R778<=50%,"=<50",">50") -> =<50 | T778: =ROUNDUP(Q778/15,0) -> 1 | U778: =T778/2 -> 0.5

Sheet Report ML>50
A1: Can be transferred | B1: >50
A3: Count of AppID
A4: School/Major | B4: Engineering | C4: Major Dont exists in IU | D4: Major exists in IU | E4: Grand Total
A5: SoAS | C5: 55 | D5: 136 | E5: 191
A6: Bachelor of Arts in Communication Arts - Advertising | D6: 6 | E6: 6
A7: Bachelor of Arts in Communication Arts - Journalism | D7: 4 | E7: 4
A8: Bachelor of Arts in Communication Arts - Public Relations | D8: 9 | E8: 9
A9: Bachelor of Arts in Communication Arts - Radio and Television | D9: 9 | E9: 9
A10: Bachelor of Communication Arts (Advertising) | D10: 1 | E10: 1
A11: Bachelor of Communication Arts (Journalism) | D11: 1 | E11: 1
A12: Bachelor of Communication Arts (Public Relations) | D12: 1 | E12: 1
A13: Bachelor of Arts in Graphic Design | D13: 30 | E13: 30
A14: Bachelor of Graphic Design | D14: 2 | E14: 2
A15: Bachelor of Arts in Interior Design | D15: 19 | E15: 19
A16: Bachelor of Biochemisrty | C16: 1 | E16: 1
A17: Bachelor of Computer Science | D17: 1 | E17: 1
A18: Bachelor of Nutrition and Dietetics | C18: 1 | E18: 1
A19: Bachelor of Science in Biomedical Science | C19: 28 | E19: 28
A20: Bachelor of Science in Computer Science | D20: 52 | E20: 52
A21: Bachelor of Science in Food Science Technology | C21: 1 | E21: 1
A22: Bachelor of Science in Information Technology | D22: 1 | E22: 1
A23: Bachelor of Science in Nutrition and Dietetics | C23: 24 | E23: 24
A24: SoBU | C24: 20 | D24: 122 | E24: 142
A25: Bachelor of Business Administration - Financial Sciences Concentration | D25: 2 | E25: 2
A26: Bachelor of Business Administration - Management of Information Systems Concentration | D26: 2 | E26: 2
A27: Bachelor of Business Administration - Marketing Concentration | D27: 1 | E27: 1
A28: Bachelor of Business Administration in Accounting Information Systems | C28: 20 | E28: 20
A29: Bachelor of Business Administration in Banking and Finance | D29: 12 | E29: 12
A30: Bachelor of Business Administration in Business Management | D30: 37 | E30: 37
A31: Bachelor of Business Administration in Hospitality and Tourism Management | D31: 4 | E31: 4
A32: Bachelor of Business Administration in International Business Management | D32: 5 | E32: 5
A33: Bachelor of Business Administration in Management Information Systems | D33: 20 | E33: 20
A34: Bachelor of Business Administration in Marketing | D34: 39 | E34: 39
A35: SoED | D35: 1 | E35: 1
A36: Bachelor of Education in Early Childhood Education | D36: 1 | E36: 1
A37: SoEN | B37: 35 | E37: 35
A38: Bachelor of Science in Biomedical Engineering | B38: 1 | E38: 1
A39: Bachelor of Science in Communication Engineering | B39: 1 | E39: 1
A40: Bachelor of Science in Computer Engineering | B40: 2 | E40: 2
A41: Bachelor of Science in Electrical Engineering | B41: 5 | E41: 5
...

Sheet Report ML<=50
A1: Can be transferred | B1: =<50
A3: Count of AppID
A4: Row Labels | B4: Can be Transferred to Bachelor of Engineering | C4: Major Dont exists in IU | D4: Major exists in IU | E4: Grand Total
A5: SoAS | C5: 46 | D5: 106 | E5: 152
A6: underGraduate | C6: 46 | D6: 106 | E6: 152
A7: Bachelor of Arts in Communication Arts - Advertising | D7: 2 | E7: 2
A8: Bachelor of Arts in Communication Arts - Journalism | D8: 1 | E8: 1
A9: Bachelor of Arts in Communication Arts - Public Relations | D9: 1 | E9: 1
A10: Bachelor of Arts in Communication Arts - Radio and Television | D10: 1 | E10: 1
A11: Bachelor of Arts in Graphic Design | D11: 6 | E11: 6
A12: Bachelor of Arts in Interior Design | D12: 8 | E12: 8
A13: Bachelor of Biochemisrty | C13: 1 | E13: 1
A14: Bachelor of Biology | C14: 5 | E14: 5
A15: Bachelor of Biomedical Sciences | C15: 10 | E15: 10
A16: Bachelor of Communication Arts (Advertising) | D16: 5 | E16: 5
A17: Bachelor of Communication Arts (Public Relations) | D17: 1 | E17: 1
A18: Bachelor of Communication Arts (Radio and Television) | D18: 7 | E18: 7
A19: Bachelor of Computer Science | D19: 17 | E19: 17
A20: Bachelor of Food Technology | C20: 2 | E20: 2
A21: Bachelor of Graphic Design | D21: 9 | E21: 9
A22: Bachelor of Information Technology | D22: 1 | E22: 1
A23: Bachelor of Interior Design | D23: 27 | E23: 27
A24: Bachelor of Mathematics | D24: 1 | E24: 1
A25: Bachelor of Nutrition and Dietetics | C25: 8 | E25: 8
A26: Bachelor of Science in Biochemistry | C26: 3 | E26: 3
A27: Bachelor of Science in Biology | C27: 1 | E27: 1
A28: Bachelor of Science in Biomedical Science | C28: 7 | E28: 7
A29: Bachelor of Science in Computer Science | D29: 18 | E29: 18
A30: Bachelor of Science in Food Science Technology | C30: 1 | E30: 1
A31: Bachelor of Science in Information Technology | D31: 1 | E31: 1
A32: Bachelor of Science in Mathematics | C32: 1 | E32: 1
A33: Bachelor of Science in Nutrition and Dietetics | C33: 7 | E33: 7
A34: SoBU | C34: 13 | D34: 144 | E34: 157
A35: underGraduate | C35: 13 | D35: 144 | E35: 157
A36: Bachelor of Business Administration - Accounting Concentration | C36: 7 | E36: 7
A37: Bachelor of Business Administration - Business Management Concentration | D37: 23 | E37: 23
A38: Bachelor of Business Administration - Economics Concentration | D38: 1 | E38: 1
A39: Bachelor of Business Administration - Financial Sciences Concentration | D39: 17 | E39: 17
A40: Bachelor of Business Administration - Hotel and Tourism Management Concentration | D40: 4 | E40: 4
A41: Bachelor of Business Administration - Management of Information Systems Concentration | D41: 24 | E41: 24
...
